Workbook

Sheet 🔥 Calcolatore
B2: CALCOLATORE CALORICO PERSONALIZZATO
B3: Edoardo Baldini · TDEE · Deficit intelligente selezionabile
B5: DATI PERSONALI | G5: I TUOI RISULTATI
B6: Peso corporeo | D6: 68 | E6: kg | G6: Metabolismo Basale (BMR) | I6: =IF(D9="M",10*D6+6.25*D7-5*D8+5,10*D6+6.25*D7-5*D8-161) -> 1242.75
B7: Altezza | D7: 163 | E7: cm | G7: Fabbisogno Totale (TDEE) | I7: =I6*D12 -> 1708.7812 | M7: Questo strumento fornisce stime basate su formule validate scientificamente, ma non sostituisce il parere di medico, nutrizionista o dietista.
B8: Età | D8: 59 | E8: anni | G8: ="KCAL TARGET (–"&VLOOKUP(D10,$F$20:$G$21,2,0)&" deficit)" -> KCAL TARGET (–500 deficit) | I8: =I7-VLOOKUP(D10,$F$20:$G$21,2,0) -> 1208.7812 | M8: Prima di iniziare qualsiasi regime dietetico, specialmente in presenza di patologie, consulta un professionista della salute.
B9: Sesso (M / F) | D9: F
B10: Deficit calorico | D10: 500 – RICOMPOSIZIONE CORPOREA | E10: kcal | G10: MACRONUTRIENTI CONSIGLIATI
B11: LIVELLO DI ATTIVITÀ FISICA | G11: Proteine (2g × kg) | I11: =D6*2*4 -> 544 | J11: kcal
B12: Seleziona moltiplicatore → | D12: 1.375 | G12: Grassi (25% kcal) | I12: =I8*0.25 -> 302.19531 | J12: kcal
D13: 1.2 | E13: Sedentario – poco o nessun esercizio | G13: Carboidrati (resto) | I13: =I8-I11-I12 -> 362.58594 | J13: kcal
D14: 1.375 | E14: Leggermente attivo – 1-3 gg/settimana
D15: 1.55 | E15: Moderatamente attivo – 3-5 gg/settimana | G15: BMI – INDICE DI MASSA CORPOREA
D16: 1.725 | E16: Molto attivo – 6-7 gg/settimana | G16: Valore BMI | I16: =D6/(D7/100)^2 -> 25.593737 | J16: =IF(I16<18.5,"⚠ Sottopeso",IF(I16<25,"✅ Normopeso",IF(I16<30,"⚠ Sovrappeso","🔴 Obesità"))) -> ⚠ Sovrappeso
D17: 1.9 | E17: Estremamente attivo – lavoro fisico intenso | G17: ="Peso attivo: "&TEXT(D6,"0.0")&" kg [ aggiorna qui quando il peso cambia ]" -> Peso attivo: 68,0 kg [ aggiorna qui quando il peso cambia ]
F20: 500 – RICOMPOSIZIONE CORPOREA | G20: 500
F21: 800 – DEFINIZIONE | G21: 800

Sheet 📅 Piano Settimanale
B2: PIANO SETTIMANALE & MONITORAGGIO PESO
B4: Giorno | C4: Peso kg | D4: Kcal Mangiate | E4: Attività | F4: Sonno h | G4: Acqua L | H4: Note
B5: Lunedì
B6: Martedì
B7: Mercoledì
B8: Giovedì
B9: Venerdì
B10: Sabato
B11: Domenica
B12: MEDIA SETTIMANA | C12: =IFERROR(AVERAGE(C5:C11),"") | D12: =IFERROR(AVERAGE(D5:D11),"") | E12: =IFERROR(AVERAGE(E5:E11),"") | F12: =IFERROR(AVERAGE(F5:F11),"") | G12: =IFERROR(AVERAGE(G5:G11),"") | H12: =IFERROR(AVERAGE(H5:H11),"")
B15: 📊 CONFRONTO SETTIMANALE — ANDAMENTO NEL TEMPO
B16: Inserisci la media settimanale · Confronta peso, kcal, sonno e acqua settimana per settimana
B17: Settimana | C17: Data inizio | D17: Peso medio (kg) | E17: Kcal medie /giorno | F17: Attività (gg/sett) | G17: Sonno (h) | H17: Acqua (L)
B18: Settimana 1
B19: Settimana 2
B20: Settimana 3
B21: Settimana 4
B22: Settimana 5
B23: Settimana 6
B24: Settimana 7
B25: Settimana 8
B26: △ VARIAZIONE Sett.1 → Sett.8 | D26: =IFERROR(D25-D18,"") -> 0 | E26: =IFERROR(E25-E18,"") -> 0 | F26: =IFERROR(F25-F18,"") -> 0 | G26: =IFERROR(G25-G18,"") -> 0 | H26: =IFERROR(H25-H18,"") -> 0
B27: COSA FARE SE IL PESO NON SCENDE
B28: 1. ASPETTA ALMENO 2-3 SETTIMANE
B29: Il peso fluttua ogni giorno per ritenzione idrica, ciclo, sale, ecc. Confronta la media settimanale — non il singolo giorno — su almeno 2 settimane. Solo allora decidi se agire.
B31: 2. CONTROLLA LE KCAL REALI
B32: Molte persone sottostimano le kcal del 30-50%. Pesa gli alimenti con una bilancia da cucina e traccia tutto per 1-2 settimane con un'app (MyFitnessPal, Cronometer).
B34: 3. RIDUCI DI ULTERIORI 100-200 KCAL
B35: Se dopo 3 settimane la media non scende, riduci il target di 100-200 kcal. Soglia minima sicura: 1.200 kcal per le donne, 1.400 kcal per gli uomini.
B37: 4. AUMENTA L'ATTIVITÀ QUOTIDIANA
B38: Aggiungi 2.000-3.000 passi/giorno o una sessione cardio extra a settimana. Il movimento NEAT (camminare, scale, faccende) brucia più calorie di quanto pensi.
B40: 5. RICALCOLA LE TUE KCAL (peso bloccato da 2+ settimane)
B41: Se dopo 2 settimane la media del peso non si muove, torna al foglio Calcolatore e aggiorna il campo PESO CORPOREO con il tuo peso attuale. Le kcal target, i macronutrienti e le porzioni della dieta si ricalcolano automaticamente. Con ogni kg perso il metabolismo rallenta leggermente: ricalcolare è essenziale per continuare a progredire.
B43: 6. DORMI E GESTISCI LO STRESS
... B47: Con la dieta ipocalorica rischi di perdere muscolo. Mantieni almeno 1.8-2g di proteine per kg di peso. Il muscolo brucia più calorie a riposo e dà forma al corpo.

Sheet 📚 Guida Completa
B2: GUIDA COMPLETA AL DEFICIT CALORICO
B4: COME FUNZIONA IL CALCOLO
B5: Questo strumento usa la formula Mifflin-St Jeor, la più accurata disponibile per stimare il metabolismo basale (BMR). Il BMR viene poi moltiplicato per il fattore di attività per ottenere il TDEE — le calorie totali bruciate ogni giorno.
B6: Dal TDEE vengono sottratte 800 kcal creando un deficit sicuro ed efficace (~0.7-1 kg/settimana) senza rischiare perdita muscolare o rallentamento metabolico.
B7: LE FORMULE
B8: UOMINI: BMR = (10 × peso kg) + (6.25 × altezza cm) − (5 × età) + 5
B9: DONNE: BMR = (10 × peso kg) + (6.25 × altezza cm) − (5 × età) − 161
B10: TDEE = BMR × fattore attività | TARGET = TDEE − 800 kcal
B11: TIMELINE REALISTICA
B12: Sett. 1-2: perdi 1-3 kg rapidamente. È principalmente acqua e glicogeno, non grasso. Normale e atteso.
B13: Sett. 3-8: la perdita si stabilizza a 0.5-1 kg/settimana. Questa è la vera perdita di grasso.
B14: Sett. 9+: il ritmo potrebbe calare. Aggiorna il peso nel Calcolatore ogni 4-6 settimane o ogni volta che il peso si blocca per 2+ settimane.
... B31: Questo strumento fornisce stime basate su formule validate scientificamente, ma non sostituisce il parere di medico, nutrizionista o dietista. Prima di iniziare qualsiasi regime dietetico, specialmente in presenza di patologie, consulta un professionista della salute.

Sheet 🍽️ Dieta 4 Pasti
B2: ESEMPIO DIETA GIORNALIERA PERSONALIZZATA | K2: OPZIONI VEGANE
B3: ="Piano basato su: "&TEXT('🔥 Calcolatore'!D6,"0.0")&" kg | Target: "&TEXT('🔥 Calcolatore'!I8,"#,##0")&" kcal | Porzioni aggiornate automaticamente" -> Piano basato su: 68,0 kg | Target: 1.209 kcal | Porzioni aggiornate automaticamente | K3: Swap 100% vegetali — stessa quantità, macro simili
B4: Il tuo TARGET giornaliero | D4: ='🔥 Calcolatore'!I8 -> 1208.7812 | E4: kcal/giorno
B5: Proteine Proteine target | C5: ='🔥 Calcolatore'!I11/4 -> 136 | D5: Grassi Grassi target | E5: ='🔥 Calcolatore'!I12/9 -> 33.577257 | F5: Carbs Carbs target | G5: ='🔥 Calcolatore'!I13/4 -> 90.646484
B7: COLAZIONE
B8: ~25-30% delle kcal giornaliere · Ricca di proteine per partire con energia
B9: Alimento | C9: g | D9: Kcal | E9: Prot (g) | F9: Carbs (g) | G9: Grassi (g) | I9: Alternative consigliate | K9: Opzioni Vegane
B10: ="Uova intere ("& MAX(1,ROUND(110*('🔥 Calcolatore'!I8/1911)/55,0)) &" uova)" -> Uova intere (1 uova) | C10: =ROUND(110*(('🔥 Calcolatore'!I8/1911))/5,0)*5 -> 70 | D10: =ROUND(171*(('🔥 Calcolatore'!I8/1911)),0) -> 108 | E10: =ROUND(14.3*(('🔥 Calcolatore'!I8/1911)),1) -> 9 | F10: =ROUND(1.2*(('🔥 Calcolatore'!I8/1911)),1) -> 0.8 | G10: =ROUND(12.1*(('🔥 Calcolatore'!I8/1911)),1) -> 7.7 | I10: ="Ricotta intera "& ROUND(130*('🔥 Calcolatore'!I8/1911)/5,0)*5 &"g"&" | ""Formaggio fresco "& ROUND(160*('🔥 Calcolatore'!I8/1911)/5,0)*5 &"g"&" | ""Crescenza "& ROUND(135*('🔥 Calcolatore'!I8/1911)/5,0)*5 &"g"&" | ""Stracchino "& ROUND(175*('🔥 Calcolatore'!I8/1911)/5,0)*5 &"g"&" | ""Quark intero "& ROUND(150*('🔥 Calcolatore'!I8/1911)/5,0)*5 &"g + olio EVO 8g"&" | ""Fiocchi di latte "& ROUND(100*('🔥 Calcolatore'!I8/1911)/5,0)*5 &"g + olio EVO 10g"&" | ""Prosciutto cotto "& ROUND(110*('🔥 Calcolatore'!I8/1911)/5,0)*5 &"g + olio EVO 7g"&" | ""Tonno al naturale "& ROUND(100*('🔥 Calcolatore'!I8/1911)/5,0)*5 &"g + olio EVO 8g"&" | ""Tacchino a fette "& ROUND(100*('🔥 Calcolatore'!I8/1911)/5,0)*5 &"g + olio EVO 8g"&" | ""Whey isolate "& ROUND(25*('🔥 Calcolatore'!I8/1911)/5,0)*5 &"g + burro mandorle 12g"&" | ""Salmone affumicato "& ROUND(100*('🔥 Calcolatore'!I8/1911)/5,0)*5 &"g"&" | ""Tacchino a fette "& ROUND(90*('🔥 Calcolatore'!I8/1911)/5,0)*5 &"g + noci 15g"&" | ""Bresaola "& ROUND(60*('🔥 Calcolatore'!I8/1911)/5,0)*5 &"g + fondente 85% 15g"&" | ""Sgombro al naturale "& ROUND(120*('🔥 Calcolatore'!I8/1911)/5,0)*5 &"g" -> Ricotta intera 80g | "Formaggio fresco 100g | "Crescenza 85g | "Stracchino 110g | "Quark intero 95g + olio EVO 8g | "Fiocchi di latte 65g + olio EVO 10g | "Prosciutto cotto 70g + olio EVO 7g | "Tonno al naturale 65g + olio EVO 8g | "Tacchino a fette 65g + olio EVO 8g | "Whey isolate 15g + burro mandorle 12g | "Salmone affumicato 65g | "Tacchino a fette 55g + noci 15g | "Bresaola 40g + fondente 85% 15g | "Sgombro al naturale 75g | K10: ="Tofu strapazzato con curcuma "& ROUND(150*('🔥 Calcolatore'!I8/1911)/5,0)*5 &"g"&" | ""Frittata di ceci (farinata) "& ROUND(130*('🔥 Calcolatore'!I8/1911)/5,0)*5 &"g"&" | ""Tempeh a fette "& ROUND(100*('🔥 Calcolatore'!I8/1911)/5,0)*5 &"g"&" | ""Lupini sgusciati "& ROUND(110*('🔥 Calcolatore'!I8/1911)/5,0)*5 &"g"&" | ""Proteine vegane in polvere "& ROUND(35*('🔥 Calcolatore'!I8/1911)/5,0)*5 &"g + latte vegetale 200ml" -> Tofu strapazzato con curcuma 95g | "Frittata di ceci (farinata) 80g | "Tempeh a fette 65g | "Lupini sgusciati 70g | "Proteine vegane in polvere 20g + latte vegetale 200ml
B11: Albumi (3 albumi) | C11: =ROUND(110*(('🔥 Calcolatore'!I8/1911))/5,0)*5 -> 70 | D11: =ROUND(57*(('🔥 Calcolatore'!I8/1911)),0) -> 36 | E11: =ROUND(12.1*(('🔥 Calcolatore'!I8/1911)),1) -> 7.7 | F11: =ROUND(0.8*(('🔥 Calcolatore'!I8/1911)),1) -> 0.5 | G11: =ROUND(0.2*(('🔥 Calcolatore'!I8/1911)),1) -> 0.1 | I11: ="Whey protein "&ROUND(15*(('🔥 Calcolatore'!I8/1911))/5,0)*5&"g"&" | "&"Prosciutto cotto magro "&ROUND(50*(('🔥 Calcolatore'!I8/1911))/5,0)*5&"g"&" | "&"Bresaola "&ROUND(40*(('🔥 Calcolatore'!I8/1911))/5,0)*5&"g"&" | "&"Fesa di tacchino "&ROUND(55*(('🔥 Calcolatore'!I8/1911))/5,0)*5&"g"&" | "&"Fiocchi di latte magri "&ROUND(80*(('🔥 Calcolatore'!I8/1911))/5,0)*5&"g"&" | "&"Skyr "&ROUND(90*(('🔥 Calcolatore'!I8/1911))/5,0)*5&"g"&" | "&"Tonno al naturale "&ROUND(55*(('🔥 Calcolatore'!I8/1911))/5,0)*5&"g" -> Whey protein 10g | Prosciutto cotto magro 30g | Bresaola 25g | Fesa di tacchino 35g | Fiocchi di latte magri 50g | Skyr 55g | Tonno al naturale 35g | K11: ="Tofu silken "& ROUND(120*('🔥 Calcolatore'!I8/1911)/5,0)*5 &"g"&" | ""Edamame bolliti "& ROUND(100*('🔥 Calcolatore'!I8/1911)/5,0)*5 &"g"&" | ""Tempeh "& ROUND(80*('🔥 Calcolatore'!I8/1911)/5,0)*5 &"g"&" | ""Lupini sgusciati "& ROUND(100*('🔥 Calcolatore'!I8/1911)/5,0)*5 &"g"&" | ""Proteine vegane "& ROUND(20*('🔥 Calcolatore'!I8/1911)/5,0)*5 &"g in acqua" -> Tofu silken 75g | "Edamame bolliti 65g | "Tempeh 50g | "Lupini sgusciati 65g | "Proteine vegane 15g in acqua
B12: Pane integrale tostato | C12: =ROUND(65*(('🔥 Calcolatore'!I8/1911))/5,0)*5 -> 40 | D12: =ROUND(168*(('🔥 Calcolatore'!I8/1911)),0) -> 106 | E12: =ROUND(6.5*(('🔥 Calcolatore'!I8/1911)),1) -> 4.1 | F12: =ROUND(31.4*(('🔥 Calcolatore'!I8/1911)),1) -> 19.9 | G12: =ROUND(1.6*(('🔥 Calcolatore'!I8/1911)),1) -> 1 | I12: ="Fette biscottate integrali "&ROUND(45*(('🔥 Calcolatore'!I8/1911))/5,0)*5&"g"&" | "&"Crackers integrali "&ROUND(40*(('🔥 Calcolatore'!I8/1911))/5,0)*5&"g"&" | "&"Pane di segale "&ROUND(75*(('🔥 Calcolatore'!I8/1911))/5,0)*5&"g"&" | "&"Avena fiocchi porridge "&ROUND(45*(('🔥 Calcolatore'!I8/1911))/5,0)*5&"g"&" | "&"Muesli senza zucchero "&ROUND(45*(('🔥 Calcolatore'!I8/1911))/5,0)*5&"g" -> Fette biscottate integrali 30g | Crackers integrali 25g | Pane di segale 45g | Avena fiocchi porridge 30g | Muesli senza zucchero 30g | K12: ="Avena "& ROUND(60*('🔥 Calcolatore'!I8/1911)/5,0)*5 &"g con latte vegetale"&" | ""Gallette di riso 5 pz"&" | ""Pane di segale "& ROUND(60*('🔥 Calcolatore'!I8/1911)/5,0)*5 &"g"&" | ""Fiocchi di farro "& ROUND(55*('🔥 Calcolatore'!I8/1911)/5,0)*5 &"g" -> Avena 40g con latte vegetale | "Gallette di riso 5 pz | "Pane di segale 40g | "Fiocchi di farro 35g
B13: Yogurt greco 0% grassi | C13: =ROUND(145*(('🔥 Calcolatore'!I8/1911))/5,0)*5 -> 90 | D13: =ROUND(85*(('🔥 Calcolatore'!I8/1911)),0) -> 54 | E13: =ROUND(14.5*(('🔥 Calcolatore'!I8/1911)),1) -> 9.2 | F13: =ROUND(4.8*(('🔥 Calcolatore'!I8/1911)),1) -> 3 | G13: =ROUND(0.4*(('🔥 Calcolatore'!I8/1911)),1) -> 0.3 | I13: ="Petto di pollo cotto "&ROUND(45*(('🔥 Calcolatore'!I8/1911))/5,0)*5&"g"&" | "&"Fesa di tacchino "&ROUND(60*(('🔥 Calcolatore'!I8/1911))/5,0)*5&"g"&" | "&"Bresaola "&ROUND(45*(('🔥 Calcolatore'!I8/1911))/5,0)*5&"g"&" | "&"Tonno al naturale "&ROUND(60*(('🔥 Calcolatore'!I8/1911))/5,0)*5&"g"&" | "&"Merluzzo lessato "&ROUND(85*(('🔥 Calcolatore'!I8/1911))/5,0)*5&"g"&" | "&"Prosciutto cotto magro "&ROUND(80*(('🔥 Calcolatore'!I8/1911))/5,0)*5&"g"&" | "&"Albumi cotti (≈4 albumi) "&ROUND(130*(('🔥 Calcolatore'!I8/1911))/5,0)*5&"g" -> Petto di pollo cotto 30g | Fesa di tacchino 40g | Bresaola 30g | Tonno al naturale 40g | Merluzzo lessato 55g | Prosciutto cotto magro 50g | Albumi cotti (≈4 albumi) 80g | K13: ="Yogurt di soia proteico "& ROUND(150*('🔥 Calcolatore'!I8/1911)/5,0)*5 &"g"&" | ""Kefir di soia "& ROUND(200*('🔥 Calcolatore'!I8/1911)/5,0)*5 &"ml"&" | ""Tofu silken frullato "& ROUND(150*('🔥 Calcolatore'!I8/1911)/5,0)*5 &"g" -> Yogurt di soia proteico 95g | "Kefir di soia 125ml | "Tofu silken frullato 95g
B14: Frutta fresca (es. fragole) | C14: =ROUND(100*(('🔥 Calcolatore'!I8/1911))/5,0)*5 -> 65 | D14: =ROUND(33*(('🔥 Calcolatore'!I8/1911)),0) -> 21 | E14: =ROUND(0.7*(('🔥 Calcolatore'!I8/1911)),1) -> 0.4 | F14: =ROUND(7.7*(('🔥 Calcolatore'!I8/1911)),1) -> 4.9 | G14: =ROUND(0.3*(('🔥 Calcolatore'!I8/1911)),1) -> 0.2 | I14: ="Banana "&ROUND(35*(('🔥 Calcolatore'!I8/1911))/5,0)*5&"g"&" | "&"Mela "&ROUND(65*(('🔥 Calcolatore'!I8/1911))/5,0)*5&"g"&" | "&"Pera "&ROUND(65*(('🔥 Calcolatore'!I8/1911))/5,0)*5&"g"&" | "&"Arancia "&ROUND(75*(('🔥 Calcolatore'!I8/1911))/5,0)*5&"g"&" | "&"Kiwi "&ROUND(65*(('🔥 Calcolatore'!I8/1911))/5,0)*5&"g"&" | "&"Frutti di bosco "&ROUND(70*(('🔥 Calcolatore'!I8/1911))/5,0)*5&"g"&" | "&"Uva "&ROUND(50*(('🔥 Calcolatore'!I8/1911))/5,0)*5&"g"&" | "&"Albicocche "&ROUND(80*(('🔥 Calcolatore'!I8/1911))/5,0)*5&"g" -> Banana 20g | Mela 40g | Pera 40g | Arancia 45g | Kiwi 40g | Frutti di bosco 45g | Uva 30g | Albicocche 50g | K14: ="Mirtilli "& ROUND(120*('🔥 Calcolatore'!I8/1911)/5,0)*5 &"g"&" | ""Banana "& ROUND(100*('🔥 Calcolatore'!I8/1911)/5,0)*5 &"g"&" | ""Kiwi 2 pz"&" | ""Arancia "& ROUND(180*('🔥 Calcolatore'!I8/1911)/5,0)*5 &"g" -> Mirtilli 75g | "Banana 65g | "Kiwi 2 pz | "Arancia 115g
B15: Caffè / tè (senza zucchero) | C15: 0 | D15: 0 | E15: 0 | F15: 0 | G15: 0 | I15: Caffè macchiato scremato 150ml | Cappuccino latte scremato 150ml | Tè verde/nero non zuccherato 250ml | Tisana 250ml | K15: Tè verde 250ml | Caffè americano 200ml | Matcha con latte di avena 200ml | Tisana 250ml — già vegano
B16: Proteine Whey (1 scoop) | C16: =ROUND(30*(('🔥 Calcolatore'!I8/1911))/5,0)*5 -> 20 | D16: =ROUND(120*(('🔥 Calcolatore'!I8/1911)),0) -> 76 | E16: =ROUND(24*(('🔥 Calcolatore'!I8/1911)),1) -> 15.2 | F16: =ROUND(2*(('🔥 Calcolatore'!I8/1911)),1) -> 1.3 | G16: =ROUND(2*(('🔥 Calcolatore'!I8/1911)),1) -> 1.3 | I16: ="Whey isolate "&ROUND(30*(('🔥 Calcolatore'!I8/1911))/5,0)*5&"g"&" | "&"Whey concentrate "&ROUND(30*(('🔥 Calcolatore'!I8/1911))/5,0)*5&"g"&" | "&"Caseina lento rilascio "&ROUND(30*(('🔥 Calcolatore'!I8/1911))/5,0)*5&"g"&" | "&"Proteine uovo in polvere "&ROUND(28*(('🔥 Calcolatore'!I8/1911))/5,0)*5&"g" -> Whey isolate 20g | Whey concentrate 20g | Caseina lento rilascio 20g | Proteine uovo in polvere 20g | K16: ="Proteine di pisello e riso "& ROUND(30*('🔥 Calcolatore'!I8/1911)/5,0)*5 &"g"&" | ""Proteine di pisello "& ROUND(32*('🔥 Calcolatore'!I8/1911)/5,0)*5 &"g"&" | ""Proteine di soia "& ROUND(28*('🔥 Calcolatore'!I8/1911)/5,0)*5 &"g"&" | ""Blend vegano 50/50 "& ROUND(30*('🔥 Calcolatore'!I8/1911)/5,0)*5 &"g" -> Proteine di pisello e riso 20g | "Proteine di pisello 20g | "Proteine di soia 20g | "Blend vegano 50/50 20g
B17: Totale Colazione | C17: =SUM(C10:C15) -> 335 | D17: =SUM(D10:D16) -> 401 | E17: =SUM(E10:E16) -> 45.6 | F17: =SUM(F10:F16) -> 30.4 | G17: =SUM(G10:G16) -> 10.6 | I17: ↑ Tutti gli swap mantengono macro simili — sostituisci liberamente | K17: Tutti gli swap vegani sono completi di proteine — combina legumi + cereali per amminoacidi completi
A18: x
B19: PRANZO
B20: ~35-40% delle kcal giornaliere · Pasto principale bilanciato
B21: Alimento | C21: g | D21: Kcal | E21: Prot (g) | F21: Carbs (g) | G21: Grassi (g) | I21: Alternative consigliate | K21: Opzioni Vegane
B22: Petto di pollo / tacchino | C22: =ROUND(190*(('🔥 Calcolatore'!I8/1911))/5,0)*5 -> 120 | D22: =ROUND(219*(('🔥 Calcolatore'!I8/1911)),0) -> 139 | E22: =ROUND(45.4*(('🔥 Calcolatore'!I8/1911)),1) -> 28.7 | F22: =ROUND(0*(('🔥 Calcolatore'!I8/1911)),1) -> 0 | G22: =ROUND(3.7*(('🔥 Calcolatore'!I8/1911)),1) -> 2.3 | I22: ="Lonza di maiale magra "&ROUND(145*(('🔥 Calcolatore'!I8/1911))/5,0)*5&"g"&" | "&"Fesa di vitello "&ROUND(210*(('🔥 Calcolatore'!I8/1911))/5,0)*5&"g"&" | "&"Bistecca di manzo magra "&ROUND(140*(('🔥 Calcolatore'!I8/1911))/5,0)*5&"g"&" | "&"Tonno al naturale "&ROUND(210*(('🔥 Calcolatore'!I8/1911))/5,0)*5&"g"&" | "&"Gamberetti "&ROUND(310*(('🔥 Calcolatore'!I8/1911))/5,0)*5&"g"&" | "&"Petto di tacchino "&ROUND(185*(('🔥 Calcolatore'!I8/1911))/5,0)*5&"g"&" | "&"Merluzzo "&ROUND(305*(('🔥 Calcolatore'!I8/1911))/5,0)*5&"g" -> Lonza di maiale magra 90g | Fesa di vitello 135g | Bistecca di manzo magra 90g | Tonno al naturale 135g | Gamberetti 195g | Petto di tacchino 115g | Merluzzo 195g | K22: ="Tofu compatto marinato "& ROUND(200*('🔥 Calcolatore'!I8/1911)/5,0)*5 &"g"&" | ""Tempeh al forno "& ROUND(150*('🔥 Calcolatore'!I8/1911)/5,0)*5 &"g"&" | ""Seitan "& ROUND(140*('🔥 Calcolatore'!I8/1911)/5,0)*5 &"g"&" | ""Legumi misti cotti "& ROUND(200*('🔥 Calcolatore'!I8/1911)/5,0)*5 &"g"&" | ""Burger di lenticchie "& ROUND(180*('🔥 Calcolatore'!I8/1911)/5,0)*5 &"g" -> Tofu compatto marinato 125g | "Tempeh al forno 95g | "Seitan 90g | "Legumi misti cotti 125g | "Burger di lenticchie 115g
B23: Riso basmati / pasta integrale | C23: =ROUND(85*(('🔥 Calcolatore'!I8/1911))/5,0)*5 -> 55 | D23: =ROUND(306*(('🔥 Calcolatore'!I8/1911)),0) -> 194 | E23: =ROUND(6.9*(('🔥 Calcolatore'!I8/1911)),1) -> 4.4 | F23: =ROUND(65.9*(('🔥 Calcolatore'!I8/1911)),1) -> 41.7 | G23: =ROUND(1.1*(('🔥 Calcolatore'!I8/1911)),1) -> 0.7 | I23: ="Pasta di grano duro "&ROUND(85*(('🔥 Calcolatore'!I8/1911))/5,0)*5&"g"&" | "&"Riso bianco "&ROUND(90*(('🔥 Calcolatore'!I8/1911))/5,0)*5&"g"&" | "&"Gnocchi di patate "&ROUND(230*(('🔥 Calcolatore'!I8/1911))/5,0)*5&"g"&" | "&"Farro perlato "&ROUND(90*(('🔥 Calcolatore'!I8/1911))/5,0)*5&"g"&" | "&"Orzo perlato "&ROUND(85*(('🔥 Calcolatore'!I8/1911))/5,0)*5&"g"&" | "&"Pane integrale "&ROUND(135*(('🔥 Calcolatore'!I8/1911))/5,0)*5&"g" -> Pasta di grano duro 55g | Riso bianco 55g | Gnocchi di patate 145g | Farro perlato 55g | Orzo perlato 55g | Pane integrale 85g | K23: ="Quinoa cotta "& ROUND(100*('🔥 Calcolatore'!I8/1911)/5,0)*5 &"g"&" | ""Pasta di ceci "& ROUND(90*('🔥 Calcolatore'!I8/1911)/5,0)*5 &"g"&" | ""Riso integrale "& ROUND(100*('🔥 Calcolatore'!I8/1911)/5,0)*5 &"g"&" | ""Grano saraceno "& ROUND(95*('🔥 Calcolatore'!I8/1911)/5,0)*5 &"g" -> Quinoa cotta 65g | "Pasta di ceci 55g | "Riso integrale 65g | "Grano saraceno 60g
B24: Verdure miste al vapore | C24: =ROUND(215*(('🔥 Calcolatore'!I8/1911))/5,0)*5 -> 135 | D24: =ROUND(54*(('🔥 Calcolatore'!I8/1911)),0) -> 34 | E24: =ROUND(2.7*(('🔥 Calcolatore'!I8/1911)),1) -> 1.7 | F24: =ROUND(8.6*(('🔥 Calcolatore'!I8/1911)),1) -> 5.4 | G24: =ROUND(0.5*(('🔥 Calcolatore'!I8/1911)),1) -> 0.3 | I24: ="Zucchine "&ROUND(200*(('🔥 Calcolatore'!I8/1911))/5,0)*5&"g"&" | "&"Melanzane "&ROUND(200*(('🔥 Calcolatore'!I8/1911))/5,0)*5&"g"&" | "&"Peperoni "&ROUND(200*(('🔥 Calcolatore'!I8/1911))/5,0)*5&"g"&" | "&"Finocchi "&ROUND(200*(('🔥 Calcolatore'!I8/1911))/5,0)*5&"g"&" | "&"Fagiolini "&ROUND(200*(('🔥 Calcolatore'!I8/1911))/5,0)*5&"g"&" | "&"Asparagi "&ROUND(200*(('🔥 Calcolatore'!I8/1911))/5,0)*5&"g"&" | "&"Cavolfiore "&ROUND(200*(('🔥 Calcolatore'!I8/1911))/5,0)*5&"g"&" | "&"Broccoli "&ROUND(200*(('🔥 Calcolatore'!I8/1911))/5,0)*5&"g" -> Zucchine 125g | Melanzane 125g | Peperoni 125g | Finocchi 125g | Fagiolini 125g | Asparagi 125g | Cavolfiore 125g | Broccoli 125g | K24: ="Zucchine "& ROUND(200*('🔥 Calcolatore'!I8/1911)/5,0)*5 &"g"&" | ""Broccoli "& ROUND(200*('🔥 Calcolatore'!I8/1911)/5,0)*5 &"g"&" | ""Spinaci "& ROUND(200*('🔥 Calcolatore'!I8/1911)/5,0)*5 &"g"&" | ""Cavolfiore "& ROUND(200*('🔥 Calcolatore'!I8/1911)/5,0)*5 &"g" -> Zucchine 125g | "Broccoli 125g | "Spinaci 125g | "Cavolfiore 125g
B25: Olio EVO (condimento) | C25: =ROUND(10*(('🔥 Calcolatore'!I8/1911))/5,0)*5 -> 5 | D25: =ROUND(90*(('🔥 Calcolatore'!I8/1911)),0) -> 57 | E25: =ROUND(0*(('🔥 Calcolatore'!I8/1911)),1) -> 0 | F25: =ROUND(0*(('🔥 Calcolatore'!I8/1911)),1) -> 0 | G25: =ROUND(10*(('🔥 Calcolatore'!I8/1911)),1) -> 6.3 | I25: ="Burro "&ROUND(12*(('🔥 Calcolatore'!I8/1911))/5,0)*5&"g"&" | "&"Parmigiano grattugiato "&ROUND(25*(('🔥 Calcolatore'!I8/1911))/5,0)*5&"g"&" | "&"Olive verdi/nere "&ROUND(80*(('🔥 Calcolatore'!I8/1911))/5,0)*5&"g"&" | "&"Avocado "&ROUND(55*(('🔥 Calcolatore'!I8/1911))/5,0)*5&"g"&" | "&"Semi di lino "&ROUND(15*(('🔥 Calcolatore'!I8/1911))/5,0)*5&"g" -> Burro 10g | Parmigiano grattugiato 15g | Olive verdi/nere 50g | Avocado 35g | Semi di lino 10g | K25: ="Avocado "& ROUND(30*('🔥 Calcolatore'!I8/1911)/5,0)*5 &"g"&" | ""Tahini "& ROUND(8*('🔥 Calcolatore'!I8/1911)/5,0)*5 &"g"&" | ""Burro di mandorle "& ROUND(8*('🔥 Calcolatore'!I8/1911)/5,0)*5 &"g"&" | ""Olive nere "& ROUND(15*('🔥 Calcolatore'!I8/1911)/5,0)*5 &"g" -> Avocado 20g | "Tahini 5g | "Burro di mandorle 5g | "Olive nere 10g
B26: Limone / spezie q.b. | C26: 0 | D26: 0 | E26: 0 | F26: 0 | G26: 0 | I26: Aceto balsamico 10ml | Senape 10g | Ketchup senza zucchero 15g | Salsa di soia 10ml | Erbe aromatiche q.b. | Peperoncino q.b. | K26: Aceto balsamico 10ml | Salsa tamari 10ml | Lievito nutrizionale 5g | Aglio e prezzemolo q.b. — già vegano
B27: Totale Pranzo | C27: =SUM(C21:C25) -> 315 | D27: =SUM(D21:D25) -> 424 | E27: =SUM(E21:E25) -> 34.8 | F27: =SUM(F21:F25) -> 47.1 | G27: =SUM(G21:G25) -> 9.6 | I27: ↑ Tutti gli swap mantengono macro simili — sostituisci liberamente | K27: Tutti gli swap vegani sono completi di proteine — combina legumi + cereali per amminoacidi completi
B29: SPUNTINO
B30: ~5-10% delle kcal · Opzionale — aiuta a non arrivare affamato a cena
B31: Alimento | C31: g | D31: Kcal | E31: Prot (g) | F31: Carbs (g) | G31: Grassi (g) | I31: Alternative consigliate | K31: Opzioni Vegane
B32: Ricotta magra | C32: =ROUND(80*(('🔥 Calcolatore'!I8/1911))/5,0)*5 -> 50 | D32: =ROUND(88*(('🔥 Calcolatore'!I8/1911)),0) -> 56 | E32: =ROUND(9*(('🔥 Calcolatore'!I8/1911)),1) -> 5.7 | F32: =ROUND(4*(('🔥 Calcolatore'!I8/1911)),1) -> 2.5 | G32: =ROUND(4*(('🔥 Calcolatore'!I8/1911)),1) -> 2.5 | I32: ="Tonno al naturale "&ROUND(40*(('🔥 Calcolatore'!I8/1911))/5,0)*5&"g"&" | "&"Prosciutto cotto magro "&ROUND(60*(('🔥 Calcolatore'!I8/1911))/5,0)*5&"g"&" | "&"Bresaola "&ROUND(30*(('🔥 Calcolatore'!I8/1911))/5,0)*5&"g"&" | "&"Fesa di tacchino "&ROUND(45*(('🔥 Calcolatore'!I8/1911))/5,0)*5&"g"&" | "&"Albumi cotti (≈3 albumi) "&ROUND(95*(('🔥 Calcolatore'!I8/1911))/5,0)*5&"g"&" | "&"Salmone affumicato "&ROUND(50*(('🔥 Calcolatore'!I8/1911))/5,0)*5&"g"&" | "&"Petto di pollo cotto "&ROUND(35*(('🔥 Calcolatore'!I8/1911))/5,0)*5&"g" -> Tonno al naturale 25g | Prosciutto cotto magro 40g | Bresaola 20g | Fesa di tacchino 30g | Albumi cotti (≈3 albumi) 60g | Salmone affumicato 30g | Petto di pollo cotto 20g | K32: ="Yogurt di soia proteico "& ROUND(120*('🔥 Calcolatore'!I8/1911)/5,0)*5 &"g"&" | ""Tofu silken "& ROUND(100*('🔥 Calcolatore'!I8/1911)/5,0)*5 &"g"&" | ""Hummus "& ROUND(80*('🔥 Calcolatore'!I8/1911)/5,0)*5 &"g"&" | ""Tempeh "& ROUND(80*('🔥 Calcolatore'!I8/1911)/5,0)*5 &"g" -> Yogurt di soia proteico 75g | "Tofu silken 65g | "Hummus 50g | "Tempeh 50g
B33: Frutta secca (mandorle/noci) | C33: =ROUND(15*(('🔥 Calcolatore'!I8/1911))/5,0)*5 -> 10 | D33: =ROUND(90*(('🔥 Calcolatore'!I8/1911)),0) -> 57 | E33: =ROUND(2.5*(('🔥 Calcolatore'!I8/1911)),1) -> 1.6 | F33: =ROUND(2.5*(('🔥 Calcolatore'!I8/1911)),1) -> 1.6 | G33: =ROUND(8*(('🔥 Calcolatore'!I8/1911)),1) -> 5.1 | I33: ="Arachidi non salate "&ROUND(15*(('🔥 Calcolatore'!I8/1911))/5,0)*5&"g"&" | "&"Anacardi "&ROUND(15*(('🔥 Calcolatore'!I8/1911))/5,0)*5&"g"&" | "&"Noci "&ROUND(15*(('🔥 Calcolatore'!I8/1911))/5,0)*5&"g"&" | "&"Mandorle "&ROUND(15*(('🔥 Calcolatore'!I8/1911))/5,0)*5&"g"&" | "&"Nocciole "&ROUND(15*(('🔥 Calcolatore'!I8/1911))/5,0)*5&"g" -> Arachidi non salate 10g | Anacardi 10g | Noci 10g | Mandorle 10g | Nocciole 10g | K33: ="Semi di chia "& ROUND(15*('🔥 Calcolatore'!I8/1911)/5,0)*5 &"g"&" | ""Burro d'arachidi "& ROUND(12*('🔥 Calcolatore'!I8/1911)/5,0)*5 &"g"&" | ""Semi di canapa "& ROUND(15*('🔥 Calcolatore'!I8/1911)/5,0)*5 &"g"&" | ""Pistacchi "& ROUND(15*('🔥 Calcolatore'!I8/1911)/5,0)*5 &"g" -> Semi di chia 10g | "Burro d'arachidi 10g | "Semi di canapa 10g | "Pistacchi 10g
B34: Frutto fresco (mela/pera) | C34: =ROUND(130*(('🔥 Calcolatore'!I8/1911))/5,0)*5 -> 80 | D34: =ROUND(68*(('🔥 Calcolatore'!I8/1911)),0) -> 43 | E34: =ROUND(0.3*(('🔥 Calcolatore'!I8/1911)),1) -> 0.2 | F34: =ROUND(17*(('🔥 Calcolatore'!I8/1911)),1) -> 10.8 | G34: =ROUND(0.3*(('🔥 Calcolatore'!I8/1911)),1) -> 0.2 | I34: ="Banana "&ROUND(75*(('🔥 Calcolatore'!I8/1911))/5,0)*5&"g"&" | "&"Mela "&ROUND(130*(('🔥 Calcolatore'!I8/1911))/5,0)*5&"g"&" | "&"Arancia "&ROUND(155*(('🔥 Calcolatore'!I8/1911))/5,0)*5&"g"&" | "&"Kiwi "&ROUND(135*(('🔥 Calcolatore'!I8/1911))/5,0)*5&"g"&" | "&"Pera "&ROUND(130*(('🔥 Calcolatore'!I8/1911))/5,0)*5&"g"&" | "&"Mandarini "&ROUND(145*(('🔥 Calcolatore'!I8/1911))/5,0)*5&"g"&" | "&"Frutti di bosco "&ROUND(160*(('🔥 Calcolatore'!I8/1911))/5,0)*5&"g" -> Banana 45g | Mela 80g | Arancia 100g | Kiwi 85g | Pera 80g | Mandarini 90g | Frutti di bosco 100g | K34: ="Banana "& ROUND(100*('🔥 Calcolatore'!I8/1911)/5,0)*5 &"g"&" | ""Frutta fresca di stagione "& ROUND(150*('🔥 Calcolatore'!I8/1911)/5,0)*5 &"g" -> Banana 65g | "Frutta fresca di stagione 95g
B35: Totale Spuntino | C35: =SUM(C32:C34) -> 140 | D35: =SUM(D32:D34) -> 156 | E35: =SUM(E32:E34) -> 7.5 | F35: =SUM(F32:F34) -> 14.9 | G35: =SUM(G32:G34) -> 7.8 | I35: ↑ Tutti gli swap mantengono macro simili — sostituisci liberamente | K35: Tutti gli swap vegani sono completi di proteine — combina legumi + cereali per amminoacidi completi
B37: CENA
B38: ~25-30% delle kcal · Leggera ma proteica per favorire recupero notturno
B39: Alimento | C39: g | D39: Kcal | E39: Prot (g) | F39: Carbs (g) | G39: Grassi (g) | I39: Alternative consigliate | K39: Opzioni Vegane
B40: Pesce (salmone / merluzzo) | C40: =ROUND(126.67*(('🔥 Calcolatore'!I8/1911))/5,0)*5 -> 80 | D40: =ROUND(162*(('🔥 Calcolatore'!I8/1911)),0) -> 102 | E40: =ROUND(25.3*(('🔥 Calcolatore'!I8/1911)),1) -> 16 | F40: =ROUND(0*(('🔥 Calcolatore'!I8/1911)),1) -> 0 | G40: =ROUND(6.3*(('🔥 Calcolatore'!I8/1911)),1) -> 4 | I40: ="Petto di pollo "&ROUND(90*(('🔥 Calcolatore'!I8/1911))/5,0)*5&"g"&" | "&"Lonza di maiale magra "&ROUND(100*(('🔥 Calcolatore'!I8/1911))/5,0)*5&"g"&" | "&"Fesa di vitello "&ROUND(140*(('🔥 Calcolatore'!I8/1911))/5,0)*5&"g"&" | "&"Bistecca di manzo magra "&ROUND(95*(('🔥 Calcolatore'!I8/1911))/5,0)*5&"g"&" | "&"Tonno al naturale "&ROUND(145*(('🔥 Calcolatore'!I8/1911))/5,0)*5&"g"&" | "&"Gamberetti "&ROUND(205*(('🔥 Calcolatore'!I8/1911))/5,0)*5&"g" -> Petto di pollo 55g | Lonza di maiale magra 65g | Fesa di vitello 90g | Bistecca di manzo magra 60g | Tonno al naturale 90g | Gamberetti 130g | K40: ="Tofu compatto grigliato "& ROUND(200*('🔥 Calcolatore'!I8/1911)/5,0)*5 &"g"&" | ""Tempeh alle erbe "& ROUND(160*('🔥 Calcolatore'!I8/1911)/5,0)*5 &"g"&" | ""Burger di lenticchie "& ROUND(180*('🔥 Calcolatore'!I8/1911)/5,0)*5 &"g"&" | ""Seitan "& ROUND(150*('🔥 Calcolatore'!I8/1911)/5,0)*5 &"g" -> Tofu compatto grigliato 125g | "Tempeh alle erbe 100g | "Burger di lenticchie 115g | "Seitan 95g
B41: Patate dolci / legumi cotti | C41: =ROUND(87*(('🔥 Calcolatore'!I8/1911))/5,0)*5 -> 55 | D41: =ROUND(75*(('🔥 Calcolatore'!I8/1911)),0) -> 47 | E41: =ROUND(1.8*(('🔥 Calcolatore'!I8/1911)),1) -> 1.1 | F41: =ROUND(17.4*(('🔥 Calcolatore'!I8/1911)),1) -> 11 | G41: =ROUND(0.1*(('🔥 Calcolatore'!I8/1911)),1) -> 0.1 | I41: ="Patate bollite "&ROUND(120*(('🔥 Calcolatore'!I8/1911))/5,0)*5&"g"&" | "&"Riso cotto "&ROUND(70*(('🔥 Calcolatore'!I8/1911))/5,0)*5&"g"&" | "&"Pasta cotta "&ROUND(60*(('🔥 Calcolatore'!I8/1911))/5,0)*5&"g"&" | "&"Lenticchie cotte "&ROUND(80*(('🔥 Calcolatore'!I8/1911))/5,0)*5&"g"&" | "&"Ceci cotti "&ROUND(55*(('🔥 Calcolatore'!I8/1911))/5,0)*5&"g"&" | "&"Fagioli borlotti cotti "&ROUND(80*(('🔥 Calcolatore'!I8/1911))/5,0)*5&"g"&" | "&"Farro cotto "&ROUND(70*(('🔥 Calcolatore'!I8/1911))/5,0)*5&"g" -> Patate bollite 75g | Riso cotto 45g | Pasta cotta 40g | Lenticchie cotte 50g | Ceci cotti 35g | Fagioli borlotti cotti 50g | Farro cotto 45g | K41: ="Lenticchie rosse cotte "& ROUND(180*('🔥 Calcolatore'!I8/1911)/5,0)*5 &"g"&" | ""Fagioli neri "& ROUND(160*('🔥 Calcolatore'!I8/1911)/5,0)*5 &"g"&" | ""Ceci al forno "& ROUND(130*('🔥 Calcolatore'!I8/1911)/5,0)*5 &"g"&" | ""Piselli "& ROUND(150*('🔥 Calcolatore'!I8/1911)/5,0)*5 &"g" -> Lenticchie rosse cotte 115g | "Fagioli neri 100g | "Ceci al forno 80g | "Piselli 95g
B42: Insalata mista grande | C42: =ROUND(200*(('🔥 Calcolatore'!I8/1911))/5,0)*5 -> 125 | D42: =ROUND(35*(('🔥 Calcolatore'!I8/1911)),0) -> 22 | E42: =ROUND(2*(('🔥 Calcolatore'!I8/1911)),1) -> 1.3 | F42: =ROUND(5.5*(('🔥 Calcolatore'!I8/1911)),1) -> 3.5 | G42: =ROUND(0.5*(('🔥 Calcolatore'!I8/1911)),1) -> 0.3 | I42: ="Pomodori "&ROUND(175*(('🔥 Calcolatore'!I8/1911))/5,0)*5&"g"&" | "&"Rucola + pomodorini "&ROUND(200*(('🔥 Calcolatore'!I8/1911))/5,0)*5&"g"&" | "&"Finocchi "&ROUND(200*(('🔥 Calcolatore'!I8/1911))/5,0)*5&"g"&" | "&"Spinaci freschi "&ROUND(200*(('🔥 Calcolatore'!I8/1911))/5,0)*5&"g"&" | "&"Cetrioli + peperoni "&ROUND(200*(('🔥 Calcolatore'!I8/1911))/5,0)*5&"g" -> Pomodori 110g | Rucola + pomodorini 125g | Finocchi 125g | Spinaci freschi 125g | Cetrioli + peperoni 125g | K42: ="Rucola "& ROUND(100*('🔥 Calcolatore'!I8/1911)/5,0)*5 &"g + pomodori 100g"&" | ""Cavolo nero massaggiato "& ROUND(120*('🔥 Calcolatore'!I8/1911)/5,0)*5 &"g"&" | ""Finocchio "& ROUND(150*('🔥 Calcolatore'!I8/1911)/5,0)*5 &"g"&" | ""Spinaci freschi "& ROUND(150*('🔥 Calcolatore'!I8/1911)/5,0)*5 &"g" -> Rucola 65g + pomodori 100g | "Cavolo nero massaggiato 75g | "Finocchio 95g | "Spinaci freschi 95g
B43: Olio EVO (condimento) | C43: =ROUND(10*(('🔥 Calcolatore'!I8/1911))/5,0)*5 -> 5 | D43: =ROUND(90*(('🔥 Calcolatore'!I8/1911)),0) -> 57 | E43: =ROUND(0*(('🔥 Calcolatore'!I8/1911)),1) -> 0 | F43: =ROUND(0*(('🔥 Calcolatore'!I8/1911)),1) -> 0 | G43: =ROUND(10*(('🔥 Calcolatore'!I8/1911)),1) -> 6.3 | I43: ="Parmigiano grattugiato "&ROUND(25*(('🔥 Calcolatore'!I8/1911))/5,0)*5&"g"&" | "&"Olive "&ROUND(80*(('🔥 Calcolatore'!I8/1911))/5,0)*5&"g"&" | "&"Avocado "&ROUND(55*(('🔥 Calcolatore'!I8/1911))/5,0)*5&"g"&" | "&"Burro "&ROUND(12*(('🔥 Calcolatore'!I8/1911))/5,0)*5&"g" -> Parmigiano grattugiato 15g | Olive 50g | Avocado 35g | Burro 10g | K43: ="Avocado "& ROUND(25*('🔥 Calcolatore'!I8/1911)/5,0)*5 &"g"&" | ""Olive nere "& ROUND(20*('🔥 Calcolatore'!I8/1911)/5,0)*5 &"g"&" | ""Tahini "& ROUND(8*('🔥 Calcolatore'!I8/1911)/5,0)*5 &"g" -> Avocado 15g | "Olive nere 15g | "Tahini 5g
B44: Totale Cena | C44: =SUM(C40:C43) -> 265 | D44: =SUM(D40:D43) -> 228 | E44: =SUM(E40:E43) -> 18.4 | F44: =SUM(F40:F43) -> 14.5 | G44: =SUM(G40:G43) -> 10.7 | I44: ↑ Tutti gli swap mantengono macro simili — sostituisci liberamente | K44: Tutti gli swap vegani sono completi di proteine — combina legumi + cereali per amminoacidi completi
...

Sheet 🍽️ Dieta 3 Pasti
B2: DIETA 3 PASTI — COLAZIONE · PRANZO · CENA
B3: ="Piano basato su: "&TEXT('🔥 Calcolatore'!D6,"0.0")&" kg | Target: "&TEXT('🔥 Calcolatore'!I8,"#,##0")&" kcal | Porzioni aggiornate automaticamente" -> Piano basato su: 68,0 kg | Target: 1.209 kcal | Porzioni aggiornate automaticamente
B4: Target giornaliero | D4: ='🔥 Calcolatore'!I8 -> 1208.7812 | E4: kcal/giorno
B5: Proteine target | C5: ='🔥 Calcolatore'!I11/4 -> 136 | D5: Grassi target | E5: ='🔥 Calcolatore'!I12/9 -> 33.577257 | F5: Carbs target | G5: ='🔥 Calcolatore'!I13/4 -> 90.646484
B7: COLAZIONE
B8: ~33-35% delle kcal · Abbondante per affrontare la giornata senza spuntini
B9: Alimento | C9: g | D9: Kcal | E9: Prot (g) | F9: Carbs (g) | G9: Grassi (g) | I9: Alternative consigliate | K9: Opzioni Vegane
B10: ="Uova intere ("& MAX(1,ROUND(150*('🔥 Calcolatore'!I8/1911)*1.015175/55,0)) &" uova)" -> Uova intere (2 uova) | C10: =ROUND(150*(('🔥 Calcolatore'!I8/1911)*1.015175)/5,0)*5 -> 95 | D10: =ROUND(233*(('🔥 Calcolatore'!I8/1911)*1.015175),0) -> 150 | E10: =ROUND(19.5*(('🔥 Calcolatore'!I8/1911)*1.015175),1) -> 12.5 | F10: =ROUND(1.6*(('🔥 Calcolatore'!I8/1911)*1.015175),1) -> 1 | G10: =ROUND(16.5*(('🔥 Calcolatore'!I8/1911)*1.015175),1) -> 10.6 | I10: ="Ricotta intera "& ROUND(130*('🔥 Calcolatore'!I8/1911)*1.015175/5,0)*5 &"g"&" | ""Formaggio fresco "& ROUND(160*('🔥 Calcolatore'!I8/1911)*1.015175/5,0)*5 &"g"&" | ""Crescenza "& ROUND(135*('🔥 Calcolatore'!I8/1911)*1.015175/5,0)*5 &"g"&" | ""Stracchino "& ROUND(175*('🔥 Calcolatore'!I8/1911)*1.015175/5,0)*5 &"g"&" | ""Quark intero "& ROUND(150*('🔥 Calcolatore'!I8/1911)*1.015175/5,0)*5 &"g + olio EVO 8g"&" | ""Fiocchi di latte "& ROUND(100*('🔥 Calcolatore'!I8/1911)*1.015175/5,0)*5 &"g + olio EVO 10g"&" | ""Prosciutto cotto "& ROUND(110*('🔥 Calcolatore'!I8/1911)*1.015175/5,0)*5 &"g + olio EVO 7g"&" | ""Tonno al naturale "& ROUND(100*('🔥 Calcolatore'!I8/1911)*1.015175/5,0)*5 &"g + olio EVO 8g"&" | ""Tacchino a fette "& ROUND(100*('🔥 Calcolatore'!I8/1911)*1.015175/5,0)*5 &"g + olio EVO 8g"&" | ""Whey isolate "& ROUND(25*('🔥 Calcolatore'!I8/1911)*1.015175/5,0)*5 &"g + burro mandorle 12g"&" | ""Salmone affumicato "& ROUND(100*('🔥 Calcolatore'!I8/1911)*1.015175/5,0)*5 &"g"&" | ""Tacchino a fette "& ROUND(90*('🔥 Calcolatore'!I8/1911)*1.015175/5,0)*5 &"g + noci 15g"&" | ""Bresaola "& ROUND(60*('🔥 Calcolatore'!I8/1911)*1.015175/5,0)*5 &"g + fondente 85% 15g"&" | ""Sgombro al naturale "& ROUND(120*('🔥 Calcolatore'!I8/1911)*1.015175/5,0)*5 &"g" -> Ricotta intera 85g | "Formaggio fresco 105g | "Crescenza 85g | "Stracchino 110g | "Quark intero 95g + olio EVO 8g | "Fiocchi di latte 65g + olio EVO 10g | "Prosciutto cotto 70g + olio EVO 7g | "Tonno al naturale 65g + olio EVO 8g | "Tacchino a fette 65g + olio EVO 8g | "Whey isolate 15g + burro mandorle 12g | "Salmone affumicato 65g | "Tacchino a fette 60g + noci 15g | "Bresaola 40g + fondente 85% 15g | "Sgombro al naturale 75g | K10: ="Tofu strapazzato con curcuma "& ROUND(150*('🔥 Calcolatore'!I8/1911)*1.015175/5,0)*5 &"g"&" | ""Frittata di ceci (farinata) "& ROUND(130*('🔥 Calcolatore'!I8/1911)*1.015175/5,0)*5 &"g"&" | ""Tempeh a fette "& ROUND(100*('🔥 Calcolatore'!I8/1911)*1.015175/5,0)*5 &"g"&" | ""Lupini sgusciati "& ROUND(110*('🔥 Calcolatore'!I8/1911)*1.015175/5,0)*5 &"g"&" | ""Proteine vegane in polvere "& ROUND(35*('🔥 Calcolatore'!I8/1911)*1.015175/5,0)*5 &"g + latte vegetale 200ml" -> Tofu strapazzato con curcuma 95g | "Frittata di ceci (farinata) 85g | "Tempeh a fette 65g | "Lupini sgusciati 70g | "Proteine vegane in polvere 20g + latte vegetale 200ml
B11: Albumi (3 albumi) | C11: =ROUND(100*(('🔥 Calcolatore'!I8/1911)*1.015175)/5,0)*5 -> 65 | D11: =ROUND(52*(('🔥 Calcolatore'!I8/1911)*1.015175),0) -> 33 | E11: =ROUND(11*(('🔥 Calcolatore'!I8/1911)*1.015175),1) -> 7.1 | F11: =ROUND(0.7*(('🔥 Calcolatore'!I8/1911)*1.015175),1) -> 0.4 | G11: =ROUND(0.2*(('🔥 Calcolatore'!I8/1911)*1.015175),1) -> 0.1 | I11: ="Whey protein "&ROUND(15*(('🔥 Calcolatore'!I8/1911))*1.015175/5,0)*5&"g"&" | "&"Prosciutto cotto magro "&ROUND(45*(('🔥 Calcolatore'!I8/1911))*1.015175/5,0)*5&"g"&" | "&"Bresaola "&ROUND(35*(('🔥 Calcolatore'!I8/1911))*1.015175/5,0)*5&"g"&" | "&"Fesa di tacchino "&ROUND(50*(('🔥 Calcolatore'!I8/1911))*1.015175/5,0)*5&"g"&" | "&"Fiocchi di latte magri "&ROUND(70*(('🔥 Calcolatore'!I8/1911))*1.015175/5,0)*5&"g"&" | "&"Skyr "&ROUND(85*(('🔥 Calcolatore'!I8/1911))*1.015175/5,0)*5&"g"&" | "&"Tonno al naturale "&ROUND(50*(('🔥 Calcolatore'!I8/1911))*1.015175/5,0)*5&"g" -> Whey protein 10g | Prosciutto cotto magro 30g | Bresaola 20g | Fesa di tacchino 30g | Fiocchi di latte magri 45g | Skyr 55g | Tonno al naturale 30g | K11: ="Tofu silken "& ROUND(120*('🔥 Calcolatore'!I8/1911)*1.015175/5,0)*5 &"g"&" | ""Edamame bolliti "& ROUND(100*('🔥 Calcolatore'!I8/1911)*1.015175/5,0)*5 &"g"&" | ""Tempeh "& ROUND(80*('🔥 Calcolatore'!I8/1911)*1.015175/5,0)*5 &"g"&" | ""Lupini sgusciati "& ROUND(100*('🔥 Calcolatore'!I8/1911)*1.015175/5,0)*5 &"g"&" | ""Proteine vegane "& ROUND(20*('🔥 Calcolatore'!I8/1911)*1.015175/5,0)*5 &"g in acqua" -> Tofu silken 75g | "Edamame bolliti 65g | "Tempeh 50g | "Lupini sgusciati 65g | "Proteine vegane 15g in acqua
B12: Pane integrale tostato | C12: =ROUND(80*(('🔥 Calcolatore'!I8/1911)*1.015175)/5,0)*5 -> 50 | D12: =ROUND(207*(('🔥 Calcolatore'!I8/1911)*1.015175),0) -> 133 | E12: =ROUND(8*(('🔥 Calcolatore'!I8/1911)*1.015175),1) -> 5.1 | F12: =ROUND(38*(('🔥 Calcolatore'!I8/1911)*1.015175),1) -> 24.4 | G12: =ROUND(2*(('🔥 Calcolatore'!I8/1911)*1.015175),1) -> 1.3 | I12: ="Avena porridge "&ROUND(55*(('🔥 Calcolatore'!I8/1911))*1.015175/5,0)*5&"g"&" | "&"Fette biscottate integrali 5 pz "&ROUND(55*(('🔥 Calcolatore'!I8/1911))*1.015175/5,0)*5&"g"&" | "&"Pane di segale "&ROUND(90*(('🔥 Calcolatore'!I8/1911))*1.015175/5,0)*5&"g"&" | "&"Crackers integrali "&ROUND(50*(('🔥 Calcolatore'!I8/1911))*1.015175/5,0)*5&"g"&" | "&"Gallette di riso "&ROUND(55*(('🔥 Calcolatore'!I8/1911))*1.015175/5,0)*5&"g" -> Avena porridge 35g | Fette biscottate integrali 5 pz 35g | Pane di segale 60g | Crackers integrali 30g | Gallette di riso 35g | K12: ="Avena "& ROUND(70*('🔥 Calcolatore'!I8/1911)*1.015175/5,0)*5 &"g con latte vegetale"&" | ""Gallette di riso 5 pz"&" | ""Pane di farro "& ROUND(80*('🔥 Calcolatore'!I8/1911)*1.015175/5,0)*5 &"g" -> Avena 45g con latte vegetale | "Gallette di riso 5 pz | "Pane di farro 50g
B13: Yogurt greco 0% grassi | C13: =ROUND(200*(('🔥 Calcolatore'!I8/1911)*1.015175)/5,0)*5 -> 130 | D13: =ROUND(117*(('🔥 Calcolatore'!I8/1911)*1.015175),0) -> 75 | E13: =ROUND(20*(('🔥 Calcolatore'!I8/1911)*1.015175),1) -> 12.8 | F13: =ROUND(6.6*(('🔥 Calcolatore'!I8/1911)*1.015175),1) -> 4.2 | G13: =ROUND(0.6*(('🔥 Calcolatore'!I8/1911)*1.015175),1) -> 0.4 | I13: ="Petto di pollo cotto "&ROUND(63.53*(('🔥 Calcolatore'!I8/1911)*1.015175)/5,0)*5&"g"&" | "&"Fesa di tacchino "&ROUND(83.23*(('🔥 Calcolatore'!I8/1911)*1.015175)/5,0)*5&"g"&" | "&"Bresaola "&ROUND(58.6*(('🔥 Calcolatore'!I8/1911)*1.015175)/5,0)*5&"g"&" | "&"Tonno al naturale "&ROUND(78.3*(('🔥 Calcolatore'!I8/1911)*1.015175)/5,0)*5&"g"&" | "&"Merluzzo lessato "&ROUND(117.71*(('🔥 Calcolatore'!I8/1911)*1.015175)/5,0)*5&"g"&" | "&"Prosciutto cotto magro "&ROUND(107.86*(('🔥 Calcolatore'!I8/1911)*1.015175)/5,0)*5&"g"&" | "&"Albumi cotti (≈6 albumi) "&ROUND(176.81*(('🔥 Calcolatore'!I8/1911)*1.015175)/5,0)*5&"g" -> Petto di pollo cotto 40g | Fesa di tacchino 55g | Bresaola 40g | Tonno al naturale 50g | Merluzzo lessato 75g | Prosciutto cotto magro 70g | Albumi cotti (≈6 albumi) 115g | K13: ="Yogurt di soia proteico "& ROUND(200*('🔥 Calcolatore'!I8/1911)*1.015175/5,0)*5 &"g"&" | ""Yogurt di cocco "& ROUND(200*('🔥 Calcolatore'!I8/1911)*1.015175/5,0)*5 &"g"&" | ""Kefir di soia "& ROUND(250*('🔥 Calcolatore'!I8/1911)*1.015175/5,0)*5 &"ml" -> Yogurt di soia proteico 130g | "Yogurt di cocco 130g | "Kefir di soia 160ml
B14: Frutta fresca | C14: =ROUND(150*(('🔥 Calcolatore'!I8/1911)*1.015175)/5,0)*5 -> 95 | D14: =ROUND(50*(('🔥 Calcolatore'!I8/1911)*1.015175),0) -> 32 | E14: =ROUND(1*(('🔥 Calcolatore'!I8/1911)*1.015175),1) -> 0.6 | F14: =ROUND(11.5*(('🔥 Calcolatore'!I8/1911)*1.015175),1) -> 7.4 | G14: =ROUND(0.4*(('🔥 Calcolatore'!I8/1911)*1.015175),1) -> 0.3 | I14: ="Banana "&ROUND(55*(('🔥 Calcolatore'!I8/1911))*1.015175/5,0)*5&"g"&" | "&"Mela "&ROUND(95*(('🔥 Calcolatore'!I8/1911))*1.015175/5,0)*5&"g"&" | "&"Pera "&ROUND(95*(('🔥 Calcolatore'!I8/1911))*1.015175/5,0)*5&"g"&" | "&"Arancia "&ROUND(115*(('🔥 Calcolatore'!I8/1911))*1.015175/5,0)*5&"g"&" | "&"Kiwi 2 pz "&ROUND(100*(('🔥 Calcolatore'!I8/1911))*1.015175/5,0)*5&"g"&" | "&"Frutti di bosco "&ROUND(115*(('🔥 Calcolatore'!I8/1911))*1.015175/5,0)*5&"g" -> Banana 35g | Mela 60g | Pera 60g | Arancia 75g | Kiwi 2 pz 65g | Frutti di bosco 75g | K14: ="Banana "& ROUND(120*('🔥 Calcolatore'!I8/1911)*1.015175/5,0)*5 &"g"&" | ""Mela "& ROUND(170*('🔥 Calcolatore'!I8/1911)*1.015175/5,0)*5 &"g"&" | ""Frutti di bosco "& ROUND(150*('🔥 Calcolatore'!I8/1911)*1.015175/5,0)*5 &"g" -> Banana 75g | "Mela 110g | "Frutti di bosco 95g
B15: Caffè / tè (senza zucchero) | D15: 0 | E15: 0 | F15: 0 | G15: 0 | I15: Caffè macchiato scremato 150ml | Cappuccino latte scremato 150ml | Tè verde/nero non zuccherato 250ml | Tisana 250ml | K15: Tè verde 250ml | Tisana 250ml | Matcha con latte di avena 200ml
B16: Proteine Whey (1 scoop) | D16: =ROUND(120*(('🔥 Calcolatore'!I8/1911)),0) -> 76 | E16: =ROUND(24*(('🔥 Calcolatore'!I8/1911)),1) -> 15.2 | F16: =ROUND(2*(('🔥 Calcolatore'!I8/1911)),1) -> 1.3 | G16: =ROUND(2*(('🔥 Calcolatore'!I8/1911)),1) -> 1.3 | I16: ="Whey isolate "& ROUND(30*('🔥 Calcolatore'!I8/1911)*1.015175/5,0)*5 &"g (più pura, meno lattosio)"&" | ""Whey concentrate "& ROUND(32*('🔥 Calcolatore'!I8/1911)*1.015175/5,0)*5 &"g"&" | ""Caseina lento rilascio "& ROUND(30*('🔥 Calcolatore'!I8/1911)*1.015175/5,0)*5 &"g"&" | ""Proteine dell'uovo "& ROUND(28*('🔥 Calcolatore'!I8/1911)*1.015175/5,0)*5 &"g" -> Whey isolate 20g (più pura, meno lattosio) | "Whey concentrate 20g | "Caseina lento rilascio 20g | "Proteine dell'uovo 20g | K16: ="Proteine di pisello "& ROUND(30*('🔥 Calcolatore'!I8/1911)*1.015175/5,0)*5 &"g"&" | ""Proteine di riso integrale "& ROUND(32*('🔥 Calcolatore'!I8/1911)*1.015175/5,0)*5 &"g"&" | ""Proteine di soia "& ROUND(28*('🔥 Calcolatore'!I8/1911)*1.015175/5,0)*5 &"g"&" | ""Blend vegano 50/50 "& ROUND(30*('🔥 Calcolatore'!I8/1911)*1.015175/5,0)*5 &"g" -> Proteine di pisello 20g | "Proteine di riso integrale 20g | "Proteine di soia 20g | "Blend vegano 50/50 20g
B17: Totale Colazione | D17: =SUM(D10:D16) -> 499 | E17: =SUM(E10:E16) -> 53.3 | F17: =SUM(F10:F16) -> 38.7 | G17: =SUM(G10:G16) -> 14 | I17: Tutti gli swap mantengono macro simili — sostituisci liberamente | K17: Combina legumi + cereali nello stesso giorno per amminoacidi completi
B19: PRANZO
B20: ~38-40% delle kcal · Pasto principale con fonte proteica, carboidrati e verdure
B21: Alimento | C21: g | D21: Kcal | E21: Prot (g) | F21: Carbs (g) | G21: Grassi (g) | I21: Alternative consigliate | K21: Opzioni Vegane
B22: Petto di pollo / tacchino | C22: =ROUND(220*(('🔥 Calcolatore'!I8/1911)*0.855543)/5,0)*5 -> 120 | D22: =ROUND(253*(('🔥 Calcolatore'!I8/1911)*0.855543),0) -> 137 | E22: =ROUND(52.5*(('🔥 Calcolatore'!I8/1911)*0.855543),1) -> 28.4 | F22: 0 | G22: =ROUND(4.3*(('🔥 Calcolatore'!I8/1911)*0.855543),1) -> 2.3 | I22: ="Lonza di maiale magra "&ROUND(170*(('🔥 Calcolatore'!I8/1911))*0.855543/5,0)*5&"g"&" | "&"Fesa di vitello "&ROUND(240*(('🔥 Calcolatore'!I8/1911))*0.855543/5,0)*5&"g"&" | "&"Bistecca magra "&ROUND(165*(('🔥 Calcolatore'!I8/1911))*0.855543/5,0)*5&"g"&" | "&"Tonno al naturale "&ROUND(245*(('🔥 Calcolatore'!I8/1911))*0.855543/5,0)*5&"g"&" | "&"Gamberetti "&ROUND(355*(('🔥 Calcolatore'!I8/1911))*0.855543/5,0)*5&"g"&" | "&"Merluzzo "&ROUND(350*(('🔥 Calcolatore'!I8/1911))*0.855543/5,0)*5&"g" -> Lonza di maiale magra 90g | Fesa di vitello 130g | Bistecca magra 90g | Tonno al naturale 135g | Gamberetti 190g | Merluzzo 190g | K22: ="Tofu compatto "& ROUND(250*('🔥 Calcolatore'!I8/1911)*1.015175/5,0)*5 &"g"&" | ""Tempeh "& ROUND(190*('🔥 Calcolatore'!I8/1911)*1.015175/5,0)*5 &"g"&" | ""Seitan "& ROUND(175*('🔥 Calcolatore'!I8/1911)*1.015175/5,0)*5 &"g"&" | ""Legumi misti "& ROUND(250*('🔥 Calcolatore'!I8/1911)*1.015175/5,0)*5 &"g" -> Tofu compatto 160g | "Tempeh 120g | "Seitan 110g | "Legumi misti 160g
B23: Riso / pasta integrale | C23: =ROUND(100*(('🔥 Calcolatore'!I8/1911)*0.855543)/5,0)*5 -> 55 | D23: =ROUND(360*(('🔥 Calcolatore'!I8/1911)*0.855543),0) -> 195 | E23: =ROUND(8*(('🔥 Calcolatore'!I8/1911)*0.855543),1) -> 4.3 | F23: =ROUND(77.5*(('🔥 Calcolatore'!I8/1911)*0.855543),1) -> 41.9 | G23: =ROUND(1.2*(('🔥 Calcolatore'!I8/1911)*0.855543),1) -> 0.6 | I23: ="Pasta di grano duro "&ROUND(100*(('🔥 Calcolatore'!I8/1911))*0.855543/5,0)*5&"g"&" | "&"Riso bianco "&ROUND(105*(('🔥 Calcolatore'!I8/1911))*0.855543/5,0)*5&"g"&" | "&"Gnocchi di patate "&ROUND(270*(('🔥 Calcolatore'!I8/1911))*0.855543/5,0)*5&"g"&" | "&"Farro perlato "&ROUND(105*(('🔥 Calcolatore'!I8/1911))*0.855543/5,0)*5&"g"&" | "&"Orzo perlato "&ROUND(100*(('🔥 Calcolatore'!I8/1911))*0.855543/5,0)*5&"g" -> Pasta di grano duro 55g | Riso bianco 55g | Gnocchi di patate 145g | Farro perlato 55g | Orzo perlato 55g | K23: ="Quinoa cotta "& ROUND(100*('🔥 Calcolatore'!I8/1911)*1.015175/5,0)*5 &"g"&" | ""Pasta di ceci "& ROUND(90*('🔥 Calcolatore'!I8/1911)*1.015175/5,0)*5 &"g"&" | ""Riso integrale "& ROUND(100*('🔥 Calcolatore'!I8/1911)*1.015175/5,0)*5 &"g"&" | ""Bulgur "& ROUND(95*('🔥 Calcolatore'!I8/1911)*1.015175/5,0)*5 &"g" -> Quinoa cotta 65g | "Pasta di ceci 60g | "Riso integrale 65g | "Bulgur 60g
B24: Legumi (fagioli / ceci / lenticchie) | C24: =ROUND(100*(('🔥 Calcolatore'!I8/1911)*0.855543)/5,0)*5 -> 55 | D24: =ROUND(110*(('🔥 Calcolatore'!I8/1911)*0.855543),0) -> 60 | E24: =ROUND(8*(('🔥 Calcolatore'!I8/1911)*0.855543),1) -> 4.3 | F24: =ROUND(18*(('🔥 Calcolatore'!I8/1911)*0.855543),1) -> 9.7 | G24: =ROUND(0.5*(('🔥 Calcolatore'!I8/1911)*0.855543),1) -> 0.3 | I24: ="Fagioli borlotti cotti "&ROUND(95*(('🔥 Calcolatore'!I8/1911))*0.855543/5,0)*5&"g"&" | "&"Ceci cotti "&ROUND(65*(('🔥 Calcolatore'!I8/1911))*0.855543/5,0)*5&"g"&" | "&"Lenticchie cotte "&ROUND(95*(('🔥 Calcolatore'!I8/1911))*0.855543/5,0)*5&"g"&" | "&"Piselli cotti "&ROUND(110*(('🔥 Calcolatore'!I8/1911))*0.855543/5,0)*5&"g" -> Fagioli borlotti cotti 50g | Ceci cotti 35g | Lenticchie cotte 50g | Piselli cotti 60g | K24: ="Fagioli neri "& ROUND(150*('🔥 Calcolatore'!I8/1911)*1.015175/5,0)*5 &"g"&" | ""Lenticchie rosse "& ROUND(100*('🔥 Calcolatore'!I8/1911)*1.015175/5,0)*5 &"g"&" | ""Ceci "& ROUND(150*('🔥 Calcolatore'!I8/1911)*1.015175/5,0)*5 &"g" -> Fagioli neri 95g | "Lenticchie rosse 65g | "Ceci 95g
B25: Verdure miste al vapore | C25: =ROUND(250*(('🔥 Calcolatore'!I8/1911)*0.855543)/5,0)*5 -> 135 | D25: =ROUND(62*(('🔥 Calcolatore'!I8/1911)*0.855543),0) -> 34 | E25: =ROUND(3.1*(('🔥 Calcolatore'!I8/1911)*0.855543),1) -> 1.7 | F25: =ROUND(10*(('🔥 Calcolatore'!I8/1911)*0.855543),1) -> 5.4 | G25: =ROUND(0.6*(('🔥 Calcolatore'!I8/1911)*0.855543),1) -> 0.3 | I25: ="Zucchine "&ROUND(250*(('🔥 Calcolatore'!I8/1911))*0.855543/5,0)*5&"g"&" | "&"Broccoli "&ROUND(250*(('🔥 Calcolatore'!I8/1911))*0.855543/5,0)*5&"g"&" | "&"Peperoni "&ROUND(250*(('🔥 Calcolatore'!I8/1911))*0.855543/5,0)*5&"g"&" | "&"Fagiolini "&ROUND(250*(('🔥 Calcolatore'!I8/1911))*0.855543/5,0)*5&"g"&" | "&"Cavolfiore "&ROUND(250*(('🔥 Calcolatore'!I8/1911))*0.855543/5,0)*5&"g" -> Zucchine 135g | Broccoli 135g | Peperoni 135g | Fagiolini 135g | Cavolfiore 135g | K25: ="Verdure miste "& ROUND(250*('🔥 Calcolatore'!I8/1911)*1.015175/5,0)*5 &"g" -> Verdure miste 160g
B26: Olio EVO (condimento) | C26: =ROUND(12*(('🔥 Calcolatore'!I8/1911)*0.855543)/5,0)*5 -> 5 | D26: =ROUND(108*(('🔥 Calcolatore'!I8/1911)*0.855543),0) -> 58 | E26: 0 | F26: 0 | G26: =ROUND(12*(('🔥 Calcolatore'!I8/1911)*0.855543),1) -> 6.5 | I26: ="Burro "&ROUND(15*(('🔥 Calcolatore'!I8/1911))*0.855543/5,0)*5&"g"&" | "&"Parmigiano "&ROUND(28*(('🔥 Calcolatore'!I8/1911))*0.855543/5,0)*5&"g"&" | "&"Olive "&ROUND(95*(('🔥 Calcolatore'!I8/1911))*0.855543/5,0)*5&"g"&" | "&"Avocado "&ROUND(65*(('🔥 Calcolatore'!I8/1911))*0.855543/5,0)*5&"g" -> Burro 10g | Parmigiano 15g | Olive 50g | Avocado 35g | K26: ="Avocado "& ROUND(40*('🔥 Calcolatore'!I8/1911)*1.015175/5,0)*5 &"g"&" | ""Tahini "& ROUND(10*('🔥 Calcolatore'!I8/1911)*1.015175/5,0)*5 &"g"&" | ""Burro di mandorle "& ROUND(10*('🔥 Calcolatore'!I8/1911)*1.015175/5,0)*5 &"g"&" | ""Olive "& ROUND(30*('🔥 Calcolatore'!I8/1911)*1.015175/5,0)*5 &"g" -> Avocado 25g | "Tahini 5g | "Burro di mandorle 5g | "Olive 20g
B27: Limone / spezie q.b. | D27: 0 | E27: 0 | F27: 0 | G27: 0 | I27: Aceto balsamico 10ml | Senape 10g | Erbe aromatiche q.b. | Peperoncino q.b. | K27: Salsa tamari 10ml | Lievito nutrizionale 5g | Erbe aromatiche q.b. — già vegano
B28: Totale Pranzo | D28: =SUM(D21:D26) -> 484 | E28: =SUM(E21:E26) -> 38.7 | F28: =SUM(F21:F26) -> 57 | G28: =SUM(G21:G26) -> 10 | I28: Tutti gli swap mantengono macro simili — sostituisci liberamente | K28: Combina legumi + cereali nello stesso giorno per amminoacidi completi
B30: CENA
B31: ~25-27% delle kcal · Leggera ma proteica per favorire il recupero notturno
B32: Alimento | C32: g | D32: Kcal | E32: Prot (g) | F32: Carbs (g) | G32: Grassi (g) | I32: Alternative consigliate | K32: Opzioni Vegane
B33: Pesce / carne magra | C33: =ROUND(126.56*(('🔥 Calcolatore'!I8/1911)*0.92278)/5,0)*5 -> 75 | D33: =ROUND(162*(('🔥 Calcolatore'!I8/1911)*0.92278),0) -> 95 | E33: =ROUND(25.3*(('🔥 Calcolatore'!I8/1911)*0.92278),1) -> 14.8 | F33: 0 | G33: =ROUND(6.3*(('🔥 Calcolatore'!I8/1911)*0.92278),1) -> 3.7 | I33: ="Petto di pollo "&ROUND(140*(('🔥 Calcolatore'!I8/1911))*0.92278/5,0)*5&"g"&" | "&"Lonza di maiale magra "&ROUND(110*(('🔥 Calcolatore'!I8/1911))*0.92278/5,0)*5&"g"&" | "&"Fesa di vitello "&ROUND(155*(('🔥 Calcolatore'!I8/1911))*0.92278/5,0)*5&"g"&" | "&"Tonno al naturale "&ROUND(160*(('🔥 Calcolatore'!I8/1911))*0.92278/5,0)*5&"g"&" | "&"Gamberetti "&ROUND(225*(('🔥 Calcolatore'!I8/1911))*0.92278/5,0)*5&"g"&" | "&"Merluzzo "&ROUND(225*(('🔥 Calcolatore'!I8/1911))*0.92278/5,0)*5&"g" -> Petto di pollo 80g | Lonza di maiale magra 65g | Fesa di vitello 90g | Tonno al naturale 95g | Gamberetti 130g | Merluzzo 130g | K33: ="Tofu compatto "& ROUND(220*('🔥 Calcolatore'!I8/1911)*1.015175/5,0)*5 &"g"&" | ""Tempeh "& ROUND(180*('🔥 Calcolatore'!I8/1911)*1.015175/5,0)*5 &"g"&" | ""Burger di lenticchie "& ROUND(200*('🔥 Calcolatore'!I8/1911)*1.015175/5,0)*5 &"g"&" | ""Seitan "& ROUND(180*('🔥 Calcolatore'!I8/1911)*1.015175/5,0)*5 &"g" -> Tofu compatto 140g | "Tempeh 115g | "Burger di lenticchie 130g | "Seitan 115g
B34: Patate / cereali / legumi | C34: =ROUND(110.16*(('🔥 Calcolatore'!I8/1911)*0.92278)/5,0)*5 -> 65 | D34: =ROUND(94*(('🔥 Calcolatore'!I8/1911)*0.92278),0) -> 55 | E34: =ROUND(2.3*(('🔥 Calcolatore'!I8/1911)*0.92278),1) -> 1.3 | F34: =ROUND(22*(('🔥 Calcolatore'!I8/1911)*0.92278),1) -> 12.8 | G34: =ROUND(0.1*(('🔥 Calcolatore'!I8/1911)*0.92278),1) -> 0.1 | I34: ="Patate bollite "&ROUND(120*(('🔥 Calcolatore'!I8/1911))*0.92278/5,0)*5&"g"&" | "&"Riso cotto "&ROUND(70*(('🔥 Calcolatore'!I8/1911))*0.92278/5,0)*5&"g"&" | "&"Pasta cotta "&ROUND(60*(('🔥 Calcolatore'!I8/1911))*0.92278/5,0)*5&"g"&" | "&"Lenticchie cotte "&ROUND(80*(('🔥 Calcolatore'!I8/1911))*0.92278/5,0)*5&"g"&" | "&"Ceci cotti "&ROUND(55*(('🔥 Calcolatore'!I8/1911))*0.92278/5,0)*5&"g"&" | "&"Fagioli borlotti "&ROUND(80*(('🔥 Calcolatore'!I8/1911))*0.92278/5,0)*5&"g" -> Patate bollite 70g | Riso cotto 40g | Pasta cotta 35g | Lenticchie cotte 45g | Ceci cotti 30g | Fagioli borlotti 45g | K34: ="Lenticchie rosse "& ROUND(180*('🔥 Calcolatore'!I8/1911)*1.015175/5,0)*5 &"g"&" | ""Ceci "& ROUND(160*('🔥 Calcolatore'!I8/1911)*1.015175/5,0)*5 &"g"&" | ""Fagioli neri "& ROUND(180*('🔥 Calcolatore'!I8/1911)*1.015175/5,0)*5 &"g" -> Lenticchie rosse 115g | "Ceci 105g | "Fagioli neri 115g
B35: Insalata mista grande | C35: =ROUND(250*(('🔥 Calcolatore'!I8/1911)*0.92278)/5,0)*5 -> 145 | D35: =ROUND(44*(('🔥 Calcolatore'!I8/1911)*0.92278),0) -> 26 | E35: =ROUND(2.5*(('🔥 Calcolatore'!I8/1911)*0.92278),1) -> 1.5 | F35: =ROUND(6.9*(('🔥 Calcolatore'!I8/1911)*0.92278),1) -> 4 | G35: =ROUND(0.6*(('🔥 Calcolatore'!I8/1911)*0.92278),1) -> 0.4 | I35: ="Rucola + pomodori "&ROUND(250*(('🔥 Calcolatore'!I8/1911))*0.92278/5,0)*5&"g"&" | "&"Spinacino + pomodorini "&ROUND(250*(('🔥 Calcolatore'!I8/1911))*0.92278/5,0)*5&"g"&" | "&"Finocchio + cetrioli "&ROUND(250*(('🔥 Calcolatore'!I8/1911))*0.92278/5,0)*5&"g"&" | "&"Insalata mista "&ROUND(250*(('🔥 Calcolatore'!I8/1911))*0.92278/5,0)*5&"g" -> Rucola + pomodori 145g | Spinacino + pomodorini 145g | Finocchio + cetrioli 145g | Insalata mista 145g | K35: ="Insalata mista "& ROUND(200*('🔥 Calcolatore'!I8/1911)*1.015175/5,0)*5 &"g" -> Insalata mista 130g
B36: Olio EVO (condimento) | D36: =ROUND(90*(('🔥 Calcolatore'!I8/1911)*0.92278),0) -> 53 | E36: 0 | F36: 0 | G36: =ROUND(10*(('🔥 Calcolatore'!I8/1911)*0.92278),1) -> 5.8 | I36: ="Parmigiano "&ROUND(28*(('🔥 Calcolatore'!I8/1911))*0.92278/5,0)*5&"g"&" | "&"Olive "&ROUND(95*(('🔥 Calcolatore'!I8/1911))*0.92278/5,0)*5&"g"&" | "&"Avocado "&ROUND(65*(('🔥 Calcolatore'!I8/1911))*0.92278/5,0)*5&"g"&" | "&"Burro "&ROUND(15*(('🔥 Calcolatore'!I8/1911))*0.92278/5,0)*5&"g" -> Parmigiano 15g | Olive 55g | Avocado 40g | Burro 10g | K36: ="Avocado "& ROUND(30*('🔥 Calcolatore'!I8/1911)*1.015175/5,0)*5 &"g"&" | ""Olive "& ROUND(22*('🔥 Calcolatore'!I8/1911)*1.015175/5,0)*5 &"g"&" | ""Tahini "& ROUND(8*('🔥 Calcolatore'!I8/1911)*1.015175/5,0)*5 &"g" -> Avocado 20g | "Olive 15g | "Tahini 5g
B37: Totale Cena | C37: =SUM(C33:C35) -> 285 | D37: =SUM(D33:D36) -> 229 | E37: =SUM(E33:E36) -> 17.6 | F37: =SUM(F33:F36) -> 16.8 | G37: =SUM(G33:G36) -> 10 | I37: Tutti le sostituzioni mantengono macro simili — sostituisci liberamente | K37: Combina legumi + cereali nello stesso giorno per amminoacidi completi
B40: TOTALE GIORNALIERO | D40: =D17+D28+D37 -> 1212 | E40: =E17+E28+E37 -> 109.6
B41: Scarto vs Target | D41: =D40-'🔥 Calcolatore'!I8 -> 3.21875 | E41: =IFERROR(IF(ABS(D40-'🔥 Calcolatore'!I8)<120,"✅ Sei nel target",IF(D40>'🔥 Calcolatore'!I8,"⚠️ Sopra il target","⬇️ Sotto il target")),"") -> ✅ Sei nel target
B43: Senza spuntino le porzioni sono più abbondanti. Se hai fame tra i pasti nelle prime settimane, aggiungi una piccola porzione di frutta (150g) o 1 yogurt greco come spuntino libero. Le porzioni si aggiornano automaticamente: aggiorna il PESO nel foglio Calcolatore.

Sheet ⏱ Digiuno 16-8
B2: DIGIUNO INTERMITTENTE 16:8 — 1 PASTO PRINCIPALE + 1 SPUNTINO
B3: ="Piano basato su: "&TEXT('🔥 Calcolatore'!D6,"0.0")&" kg | Target: "&TEXT('🔥 Calcolatore'!I8,"#,##0")&" kcal | Finestra alimentare 8h (es. 12:00–20:00)" -> Piano basato su: 68,0 kg | Target: 1.209 kcal | Finestra alimentare 8h (es. 12:00–20:00)
B5: ⏱ PROTOCOLLO 16:8: 16 ORE di digiuno (solo acqua, caffè e tè non zuccherati) + 8 ORE di finestra alimentare con 1 pasto principale abbondante e 1 spuntino
B6: Target giornaliero | D6: ='🔥 Calcolatore'!I8 -> 1208.7812 | E6: kcal/giorno
B7: Proteine target | C7: ='🔥 Calcolatore'!I11/4 -> 136 | D7: Grassi target | E7: ='🔥 Calcolatore'!I12/9 -> 33.577257 | F7: Carboidrati target | G7: ='🔥 Calcolatore'!I13/4 -> 90.646484
B9: 🌙 DIGIUNO · dalle 20:00 alle 12:00 · Solo acqua, caffè e tè non zuccherati
I10: ="Ricotta intera "& ROUND(130*('🔥 Calcolatore'!I8/1911)*0.992582/5,0)*5 &"g"&" | ""Formaggio fresco "& ROUND(160*('🔥 Calcolatore'!I8/1911)*0.992582/5,0)*5 &"g"&" | ""Crescenza "& ROUND(135*('🔥 Calcolatore'!I8/1911)*0.992582/5,0)*5 &"g"&" | ""Fiocchi di latte "& ROUND(100*('🔥 Calcolatore'!I8/1911)*0.992582/5,0)*5 &"g + olio EVO 10g"&" | ""Quark intero "& ROUND(150*('🔥 Calcolatore'!I8/1911)*0.992582/5,0)*5 &"g + olio EVO 8g" -> Ricotta intera 80g | "Formaggio fresco 100g | "Crescenza 85g | "Fiocchi di latte 65g + olio EVO 10g | "Quark intero 95g + olio EVO 8g
B11: 🍽 PASTO PRINCIPALE (12:00 – 14:00)
B12: ~70% delle kcal · Pasto unico abbondante — proteine, carboidrati, legumi, verdure e grassi
B13: Alimento | C13: g | D13: Kcal | E13: Prot (g) | F13: Carbs (g) | G13: Grassi (g) | I13: Alternative consigliate | K13: Opzioni Vegane
B14: ="Uova intere ("& MAX(1,ROUND(110*('🔥 Calcolatore'!I8/1911)*0.992582/55,0)) &" uova)" -> Uova intere (1 uova) | C14: =ROUND(110*(('🔥 Calcolatore'!I8/1911)*0.992582)/5,0)*5 -> 70 | D14: =ROUND(171*(('🔥 Calcolatore'!I8/1911)*0.992582),0) -> 107 | E14: =ROUND(14.3*(('🔥 Calcolatore'!I8/1911)*0.992582),1) -> 9 | F14: =ROUND(1.2*(('🔥 Calcolatore'!I8/1911)*0.992582),1) -> 0.8 | G14: =ROUND(12.1*(('🔥 Calcolatore'!I8/1911)*0.992582),1) -> 7.6 | I14: ="Ricotta intera "& ROUND(130*('🔥 Calcolatore'!I8/1911)*0.992582/5,0)*5 &"g"&" | ""Formaggio fresco "& ROUND(160*('🔥 Calcolatore'!I8/1911)*0.992582/5,0)*5 &"g"&" | ""Crescenza "& ROUND(135*('🔥 Calcolatore'!I8/1911)*0.992582/5,0)*5 &"g"&" | ""Stracchino "& ROUND(175*('🔥 Calcolatore'!I8/1911)*0.992582/5,0)*5 &"g"&" | ""Quark intero "& ROUND(150*('🔥 Calcolatore'!I8/1911)*0.992582/5,0)*5 &"g + olio EVO 8g"&" | ""Fiocchi di latte "& ROUND(100*('🔥 Calcolatore'!I8/1911)*0.992582/5,0)*5 &"g + olio EVO 10g"&" | ""Prosciutto cotto "& ROUND(110*('🔥 Calcolatore'!I8/1911)*0.992582/5,0)*5 &"g + olio EVO 7g"&" | ""Tonno al naturale "& ROUND(100*('🔥 Calcolatore'!I8/1911)*0.992582/5,0)*5 &"g + olio EVO 8g"&" | ""Tacchino a fette "& ROUND(100*('🔥 Calcolatore'!I8/1911)*0.992582/5,0)*5 &"g + olio EVO 8g"&" | ""Whey isolate "& ROUND(25*('🔥 Calcolatore'!I8/1911)*0.992582/5,0)*5 &"g + burro mandorle 12g"&" | ""Salmone affumicato "& ROUND(100*('🔥 Calcolatore'!I8/1911)*0.992582/5,0)*5 &"g"&" | ""Tacchino a fette "& ROUND(90*('🔥 Calcolatore'!I8/1911)*0.992582/5,0)*5 &"g + noci 15g"&" | ""Bresaola "& ROUND(60*('🔥 Calcolatore'!I8/1911)*0.992582/5,0)*5 &"g + fondente 85% 15g"&" | ""Sgombro al naturale "& ROUND(120*('🔥 Calcolatore'!I8/1911)*0.992582/5,0)*5 &"g" -> Ricotta intera 80g | "Formaggio fresco 100g | "Crescenza 85g | "Stracchino 110g | "Quark intero 95g + olio EVO 8g | "Fiocchi di latte 65g + olio EVO 10g | "Prosciutto cotto 70g + olio EVO 7g | "Tonno al naturale 65g + olio EVO 8g | "Tacchino a fette 65g + olio EVO 8g | "Whey isolate 15g + burro mandorle 12g | "Salmone affumicato 65g | "Tacchino a fette 55g + noci 15g | "Bresaola 40g + fondente 85% 15g | "Sgombro al naturale 75g | K14: ="Tofu strapazzato con curcuma "& ROUND(150*('🔥 Calcolatore'!I8/1911)*0.992582/5,0)*5 &"g"&" | ""Frittata di ceci (farinata) "& ROUND(130*('🔥 Calcolatore'!I8/1911)*0.992582/5,0)*5 &"g"&" | ""Tempeh a fette "& ROUND(100*('🔥 Calcolatore'!I8/1911)*0.992582/5,0)*5 &"g"&" | ""Lupini sgusciati "& ROUND(110*('🔥 Calcolatore'!I8/1911)*0.992582/5,0)*5 &"g"&" | ""Proteine vegane in polvere "& ROUND(35*('🔥 Calcolatore'!I8/1911)*0.992582/5,0)*5 &"g + latte vegetale 200ml" -> Tofu strapazzato con curcuma 95g | "Frittata di ceci (farinata) 80g | "Tempeh a fette 65g | "Lupini sgusciati 70g | "Proteine vegane in polvere 20g + latte vegetale 200ml
